<?xml version="1.0"?>
<robot name="robot_one" xmlns:xacro="http://www.ros.org/wiki/xacro">

    <!-- ========== BASE LINK ========== -->
  <link name="base_link_robot_1">
    <visual>
      <geometry><box size="3.0 1.5 0.05"/></geometry>
      <origin xyz="0 0 0.1" rpy="0 0 0"/>
      <material name="grey"><color rgba="0.5 0.5 0.5 1"/></material>
    </visual>
    <collision>
      <origin xyz="0 0 0.1" rpy="0 0 0"/>
      <geometry><box size="3.0 1.5 0.05"/></geometry>
    </collision>
  </link>

    <!-- ========== JOINT 1 ========== -->
  <link name="link1_robot_1">
    <visual>
      <origin xyz="0 0 0.05" rpy="0 0 0"/>
      <geometry><cylinder length="0.1" radius="0.05"/></geometry>
      <material name="blue"><color rgba="0 0 1 1"/></material>
    </visual>
    <collision>
      <origin xyz="0 0 0.05" rpy="0 0 0"/>
      <geometry><cylinder length="0.05" radius="0.05"/></geometry>
    </collision>
    <inertial>
      <mass value="1.0"/>
      <origin xyz="0 0 0.05" rpy="0 0 0"/>
      <inertia ixx="0.01" iyy="0.01" izz="0.005" ixy="0" ixz="0" iyz="0"/>
    </inertial>
  </link>
  <joint name="joint1_robot_1" type="revolute">
    <parent link="base_link_robot_1"/>
    <child link="link1_robot_1"/>
    <origin xyz="0 0 0.1" rpy="0 0 0"/>
    <axis xyz="0 0 1"/>
    <limit effort="10" velocity="1.0" lower="-3.14" upper="3.14"/>
  </joint>

  <!-- ========== JOINT 2 ========== -->
  <link name="link2_robot_1">
    <visual>
      <origin xyz="0 0 0.105" rpy="0 0 0"/> 
      <geometry><cylinder length="0.25" radius="0.04"/></geometry>
      <material name="green"><color rgba="0 1 0 1"/></material>
    </visual>
    <collision>
      <origin xyz="0 0 0.105" rpy="0 0 0"/> 
      <geometry><cylinder length="0.15" radius="0.04"/></geometry>
    </collision>
    <inertial>
      <mass value="0.8"/>
      <origin xyz="0 0 0.105" rpy="0 0 0"/>
      <inertia ixx="0.008" iyy="0.008" izz="0.004" ixy="0" ixz="0" iyz="0"/>
    </inertial>
  </link>
  <joint name="joint2_robot_1" type="revolute">
    <parent link="link1_robot_1"/>
    <child link="link2_robot_1"/>
    <origin xyz="0 0 0.10" rpy="0 0 0"/>
    <axis xyz="0 1 0"/>
    <limit effort="10" velocity="1.0" lower="-1.31" upper="1.31"/>
  </joint>

  <!-- ========== JOINT 3 ========== -->
  <link name="link3_robot_1">
    <visual>
      <origin xyz="0 0 0.1" rpy="0 0 0"/> 
      <geometry><cylinder length="0.2" radius="0.04"/></geometry>
      <material name="red"><color rgba="1 0 0 1"/></material>
    </visual>
    <collision>
      <origin xyz="0 0 0.1" rpy="0 0 0"/> 
      <geometry><cylinder length="0.12" radius="0.04"/></geometry>
    </collision>
    <inertial>
      <mass value="0.8"/>
      <origin xyz="0 0 0.1" rpy="0 0 0"/>
      <inertia ixx="0.008" iyy="0.008" izz="0.004" ixy="0" ixz="0" iyz="0"/>
    </inertial>
  </link>
  <joint name="joint3_robot_1" type="revolute">
    <parent link="link2_robot_1"/>
    <child link="link3_robot_1"/>
    <origin xyz="0 0 0.23" rpy="0 0 0"/> 
    <axis xyz="0 1 0"/>
    <limit effort="10" velocity="1.0" lower="-2.0" upper="2.0"/>
  </joint>

  <!-- ========== JOINT 4 ========== -->
  <link name="link4_robot_1">
    <visual>
      <origin xyz="0 0 0.075" rpy="0 0 0"/>
      <geometry><cylinder length="0.15" radius="0.03"/></geometry>
      <material name="yellow"><color rgba="1 1 0 1"/></material>
    </visual>
    <collision>
      <origin xyz="0 0 0.075" rpy="0 0 0"/>
      <geometry><cylinder length="0.08" radius="0.03"/></geometry>
    </collision>
    <inertial>
      <mass value="0.5"/>
      <origin xyz="0 0 0.075" rpy="0 0 0"/>
      <inertia ixx="0.005" iyy="0.005" izz="0.003" ixy="0" ixz="0" iyz="0"/>
    </inertial>
  </link>
  <joint name="joint4_robot_1" type="revolute">
    <parent link="link3_robot_1"/>
    <child link="link4_robot_1"/>
    <origin xyz="0 0 0.19" rpy="0 0 0"/>
    <axis xyz="0 1 0"/>
    <limit effort="10" velocity="1.0" lower="-3.14" upper="3.14"/>
  </joint>

  <!-- ========== JOINT 5 ========== -->
  <link name="link5_robot_1">
    <visual>
      <origin xyz="0 0 0.05" rpy="0 0 0"/>
      <geometry><cylinder length="0.1" radius="0.03"/></geometry>
      <material name="orange"><color rgba="1 0.5 0 1"/></material>
    </visual>
    <collision>
      <origin xyz="0 0 0.05" rpy="0 0 0"/>
      <geometry><cylinder length="0.05" radius="0.03"/></geometry>
    </collision>
    <inertial>
      <mass value="0.3"/>
      <origin xyz="0 0 0.05" rpy="0 0 0"/>
      <inertia ixx="0.003" iyy="0.003" izz="0.002" ixy="0" ixz="0" iyz="0"/>
    </inertial>
  </link>
  <joint name="joint5_robot_1" type="revolute">
    <parent link="link4_robot_1"/>
    <child link="link5_robot_1"/>
    <origin xyz="0 0 0.15" rpy="0 0 0"/>
    <axis xyz="0 1 0"/>
    <limit effort="10" velocity="1.0" lower="-1.57" upper="1.57"/>
  </joint>

  <!-- ========== JOINT 6 ========== -->
  <link name="link6_robot_1">
    <visual>
      <origin xyz="0 0 0.05" rpy="0 0 0"/>
      <geometry><cylinder length="0.1" radius="0.025"/></geometry>
      <material name="purple"><color rgba="0.5 0 0.5 1"/></material>
    </visual>
    <collision>
      <origin xyz="0 0 0.05" rpy="0 0 0"/>
      <geometry><cylinder length="0.1" radius="0.025"/></geometry>
    </collision>
    <inertial>
      <mass value="0.2"/>
      <origin xyz="0 0 0.05" rpy="0 0 0"/>
      <inertia ixx="0.002" iyy="0.002" izz="0.001" ixy="0" ixz="0" iyz="0"/>
    </inertial>
  </link>
  <joint name="joint6_robot_1" type="revolute">
    <parent link="link5_robot_1"/>
    <child link="link6_robot_1"/>
    <origin xyz="0 0 0.06" rpy="0 0 0"/>
    <axis xyz="0 0 1"/>
    <limit effort="10" velocity="1.0" lower="-3.14" upper="3.14"/>
  </joint>

  <!-- ========== GRIPPER BASE ========== -->
  <link name="gripper_base_robot_1">
    <visual>
      <geometry><box size="0.15 0.02 0.02"/></geometry>
      <material name="black"><color rgba="0 0 0 1"/></material>
    </visual>
    <collision>
      <geometry><box size="0.15 0.02 0.02"/></geometry>
    </collision>
    <inertial>
      <mass value="0.3"/>
      <origin xyz="0 0 0.01" rpy="0 0 0"/>
      <inertia ixx="0.001" iyy="0.001" izz="0.001" ixy="0" ixz="0" iyz="0"/>
    </inertial>
  </link>
  <joint name="ee_fixed_robot_1" type="fixed">
    <parent link="link6_robot_1"/>
    <child link="gripper_base_robot_1"/>
    <origin xyz="0 0 0.11" rpy="0 0 0"/>
  </joint>

  <!-- ========== GRIPPER FINGERS ========== -->
  <link name="left_finger_robot_1">
    <visual>
      <geometry><box size="0.01 0.05 0.02"/></geometry>
      <origin xyz="0 0 0" rpy="-1.5708 0 0"/>
      <material name="silver"><color rgba="0.8 0.8 0.8 1"/></material>
    </visual>
    <collision>
      <geometry><box size="0.01 0.05 0.02"/></geometry>
      <origin xyz="0 0 0" rpy="-1.5708 0 0"/>
    </collision>
    <inertial>
      <mass value="0.05"/>
      <origin xyz="0.005 0 0" rpy="0 0 0"/>
      <inertia ixx="0.0001" iyy="0.0001" izz="0.0001" ixy="0" ixz="0" iyz="0"/>
    </inertial>
  </link>

  <joint name="left_gripper_joint_robot_1" type="prismatic">
    <parent link="gripper_base_robot_1"/>
    <child link="left_finger_robot_1"/>
    <origin xyz="-0.067 0 0.02" rpy="0 0 0"/> 
    <axis xyz="1 0 0"/>
    <limit effort="10" velocity="1.0" lower="0.0" upper="0.06"/>
  </joint>

  <link name="right_finger_robot_1">
     <visual>
      <geometry><box size="0.01 0.05 0.02"/></geometry>
      <origin xyz="0 0 0" rpy="-1.5708 0 0"/>
      <material name="silver"/>
    </visual>
    <collision>
      <geometry><box size="0.01 0.05 0.02"/></geometry>
      <origin xyz="0 0 0" rpy="-1.5708 0 0"/>
    </collision>
    <inertial>
      <mass value="0.05"/>
      <origin xyz="0.005 0 0" rpy="0 0 0"/>
      <inertia ixx="0.0001" iyy="0.0001" izz="0.0001" ixy="0" ixz="0" iyz="0"/>
    </inertial>
  </link>

  <joint name="right_gripper_joint_robot_1" type="prismatic">
    <parent link="gripper_base_robot_1"/>
    <child link="right_finger_robot_1"/>
    <origin xyz="0.067 0 0.02" rpy="0 0 0"/>
    <axis xyz="-1 0 0"/>
    <limit effort="10" velocity="1.0" lower="0.0" upper="0.06"/>
  </joint>

</robot>
